Workbook

Sheet _PREVENTAS_
A1: Marca temporal | B1: STATUS | C1: SEGMENTO | D1: ASESOR BO | E1: PROGRAMACION BO | F1: COMENTARIOS BO | G1: SEC | H1: SOT | I1: ASESOR | J1: LEAD | K1: TIPO DOCUMENTO | L1: N° DOCUMENTO | M1: NOMBRE COMPLETO CLIENTE | N1: FECHA NACIMIENTO | O1: LUGAR NACIMIENTO | P1: UBIGEO | Q1: AMAZONAS | R1: ANCASH | S1: APURIMAC | T1: AREQUIPA | U1: AYACUCHO | V1: CAJAMARCA | W1: CALLAO | X1: CUSCO | Y1: HUANCAVELICA | Z1: HUANUCO | AA1: ICA | AB1: JUNIN | AC1: LA LIBERTAD | AD1: LAMBAYEQUE | AE1: LIMA | AF1: LIMA METROPOLITANA | AG1: LORETO | AH1: MADRE DE DIOS | AI1: MOQUEGUA | AJ1: PASCO | AK1: PIURA | AL1: PUNO | AM1: SAN MARTIN | AN1: TACNA | AO1: TUMBES | AP1: UCAYALI | AQ1: NOMBRE PADRE | AR1: NOMBRE MADRE | AS1: CORREO ELECTRONICO | AT1: Column 81 | AU1: TELF GRABACION | AV1: TELF REFERENCIA | AW1: DIRECCION INSTALACION | AX1: PISO | AY1: INTERIOR | AZ1: COORDENADAS | BA1: REFERENCIAS | BB1: PLANO | BC1: DEPARTAMENTO | BD1: PROV / DISTRITO | BE1: TECNOLOGIA | BF1: FULL CLARO | BG1: OPERACION | BH1: OPERADOR ORIGEN | BI1: TELF A PORTAR | BJ1: MODALIDAD | BK1: TIPO SERVICIO | BL1: SERVICIO A CONTRATAR | BM1: OFERTA COMERCIAL ALTA NUEVA | BN1: PRECIO REGULAR | BO1: VELOCIDAD PLAN | BP1: LIGA1 MAX | BQ1: TELEFONO | BR1: N° DECODIFICADORES | BS1: N° MESH | BT1: TELF REGISTRO | BU1: FECHA REGISTRO | BV1: FECHA PROGRAMACION | BW1: TRAMO PROGRAMACION | BX1: FECHA INSTALACIÓN | BY1: ORDEN INSTALACION | BZ1: COD STATUS | CA1: COD DPTO | CB1: MES REG | CC1: MES INSTAL
A2: 46190.704 | B2: 7 - INSTALADA | C2: MASIVO RESIDENCIAL | D2: NAYELI | E2: 46196.583 | F2: PROCEDE | G2: 104715891 | H2: 88485225 | I2: JULIANA | J2: 960791381 | K2: DNI | L2: 72187246 | M2: MARIA DEL CARMEN SALAZAR JUUYPA | N2: 36141 | O2: AREQUIPA | P2: 912817 | T2: Arequipa | AQ2: VICTOR | AR2: GABRIELA | AS2: SALAZARMADECA@GMAIL.COM | AU2: 960791381 | AV2: 960791381 | AW2: AV. LOS BOSQUES PASAJE LOS MANGLARES MZ CH LOTE 2, LA CAMPIÑA, SOCABAYA. | AX2: 3 | AY2: 1 | AZ2: -16.45931970461676, -71.52429812641768 | BA2: ESPALDA DEL COLEGIO LA CAMPIÑA | BB2: AQSB022 | BC2: AREQUIPA | BD2: =IF(COUNTA(Q2:AP2)>0,INDEX(Q2:AP2,,max(IF(Q2:AP2<>"",COLUMN(Q2:AP2)))-16),"") -> Arequipa | BE2: HFC | BF2: SI | BG2: ALTA NUEVA | BL2: 1 PLAY | BM2: Campaña Regular | BN2: 89 | BO2: 400MBPS | BP2: NO | BQ2: NO | BR2: Ninguno | BS2: Ninguno | BU2: =IF($A2<>"", DATE(YEAR($A2),MONTH($A2),DAY($A2)),"") -> 46190 | BV2: =IF($E2<>"",DATE(YEAR($E2),MONTH($E2),DAY($E2)),"") -> 46196 | BW2: =IF($E2<>"",TEXT($E2,"HH"),"") -> 14 | BX2: 46195 | BY2: 1 | BZ2: =IF(B2<>"",VALUE(LEFT(B2)),"") -> 7 | CA2: {=IF($A2<>"",INDEX(LISTA!$M$2:$N$27,MATCH($BC2,LISTA!$N$2:$N$27,0),1),"")} -> 7 | CB2: =IF($A2<>"",MONTH(BU2),"") -> 6 | CC2: =IF($BX2<>"",MONTH(BX2),"") -> 6
A3: 46198.862 | B3: 7 - INSTALADA | C3: MASIVO RESIDENCIAL | D3: PAOLA | E3: 46200.458 | F3: ENVIAR ADELANTO 26/06 | G3: 104856405 | H3: 88648893 | I3: ANNY | J3: 989050975 | K3: DNI | L3: 72539720 | M3: AMNER CALEP PEÑA PIÑA | N3: 37407 | O3: SAN MARTIN | P3: 210701 | AM3: San Martín | AQ3: EUSEBIO | AR3: ESTALI | AS3: amnercalep2002@gmail.com | AU3: 989050975 | AV3: 989050975 | AW3: JR 3 DE OCTUBRE URB 9 DE ABRIL | AX3: 1 | AY3: S/I | AZ3: -6.48287703, -76.37514139 | BA3: JR 9 DE ABRIL | BB3: SMTP025-F | BC3: SAN MARTIN | BD3: =IF(COUNTA(Q3:AP3)>0,INDEX(Q3:AP3,,max(IF(Q3:AP3<>"",COLUMN(Q3:AP3)))-16),"") -> San Martín | BE3: FTTH | BF3: SI | BG3: ALTA NUEVA | BL3: 1 PLAY | BM3: Campaña Regular | BN3: 89 | BO3: 400MBPS | BP3: NO | BQ3: NO | BR3: Ninguno | BS3: 1 | BU3: =IF($A3<>"", DATE(YEAR($A3),MONTH($A3),DAY($A3)),"") -> 46198 | BV3: =IF($E3<>"",DATE(YEAR($E3),MONTH($E3),DAY($E3)),"") -> 46200 | BW3: =IF($E3<>"",TEXT($E3,"HH"),"") -> 11 | BX3: 46199 | BY3: 1 | BZ3: =IF(B3<>"",VALUE(LEFT(B3)),"") -> 7 | CA3: {=IF($A3<>"",INDEX(LISTA!$M$2:$N$27,MATCH($BC3,LISTA!$N$2:$N$27,0),1),"")} -> 23 | CB3: =IF($A3<>"",MONTH(BU3),"") -> 6 | CC3: =IF($BX3<>"",MONTH(BX3),"") -> 6
A4: 46193.676 | B4: 7 - INSTALADA | C4: MASIVO RESIDENCIAL | D4: PAOLA | E4: 46196.458 | F4: Nos pidieron reasignación de esta venta | G4: 104713524 | H4: 88484062 | I4: JULIANA | J4: 927604817 | K4: DNI | L4: 02737885 | M4: MILAGROS INES GUERRA RIVERA | N4: 26578 | O4: PIURA | P4: 190101 | AK4: Piura | AQ4: RUBEN | AR4: OLINDA | AS4: Sebasgu1@hotmail.com | AU4: 927604817 | AV4: 927604817 | AW4: AAHH. LOPEZ ALBUJAR MZ P LOTE 18, 26 DE OCTUBRE, PIURA. | AX4: 2 | AY4: 1 | AZ4: -5.199136608082209, -80.65140110426609 | BA4: -5.199136608082209, -80.65140110426609 | BB4: PIOC002-F | BC4: PIURA | BD4: =IF(COUNTA(Q4:AP4)>0,INDEX(Q4:AP4,,max(IF(Q4:AP4<>"",COLUMN(Q4:AP4)))-16),"") -> Piura | BE4: FTTH | BF4: NO | BG4: ALTA NUEVA | BL4: 1 PLAY + L1MAX | BM4: Campaña Regular | BN4: 110 | BO4: 500MBPS | BP4: SI | BQ4: NO | BR4: Ninguno | BS4: 1 | BU4: =IF($A4<>"", DATE(YEAR($A4),MONTH($A4),DAY($A4)),"") -> 46193 | BV4: =IF($E4<>"",DATE(YEAR($E4),MONTH($E4),DAY($E4)),"") -> 46196 | BW4: =IF($E4<>"",TEXT($E4,"HH"),"") -> 11 | BX4: 46194 | BY4: 3 | BZ4: =IF(B4<>"",VALUE(LEFT(B4)),"") -> 7 | CA4: {=IF($A4<>"",INDEX(LISTA!$M$2:$N$27,MATCH($BC4,LISTA!$N$2:$N$27,0),1),"")} -> 21 | CB4: =IF($A4<>"",MONTH(BU4),"") -> 6 | CC4: =IF($BX4<>"",MONTH(BX4),"") -> 6
A5: 46198.421 | B5: 7 - INSTALADA | C5: MASIVO RESIDENCIAL | D5: NAYELI | E5: 46198.667 | F5: PROCEDE CL QUIERE PARA HOY SI O SI | G5: 104828763 | H5: 88612463 | I5: JESSICA | J5: 936888423 | K5: DNI | L5: 47139933 | M5: RICHARDSON LUIS CORDOVA RIVERA | N5: 33617 | O5: PASCO | P5: 180114 | AB5: Chanchamayo | AQ5: LUIS ALBERTO | AR5: NELLY GLADYS | AS5: richi_cr_92@hotmail.com | AU5: 936888423 | AV5: 936888423 | AW5: JR. LAS DUNAS 130 | AX5: 2 | AY5: NA | AZ5: -12.06481115, -75.22763426 | BA5: PASAJE LAS MESETAS | BB5: JNTB067-F | BC5: JUNIN | BD5: =IF(COUNTA(Q5:AP5)>0,INDEX(Q5:AP5,,max(IF(Q5:AP5<>"",COLUMN(Q5:AP5)))-16),"") -> Chanchamayo | BE5: FTTH | BF5: NO | BG5: ALTA NUEVA | BL5: 1 PLAY | BM5: Campaña Promo Mediana | BN5: 89 | BO5: 400MBPS | BP5: NO | BQ5: NO | BR5: Ninguno | BS5: 1 | BU5: =IF($A5<>"", DATE(YEAR($A5),MONTH($A5),DAY($A5)),"") -> 46198 | BV5: =IF($E5<>"",DATE(YEAR($E5),MONTH($E5),DAY($E5)),"") -> 46198 | BW5: =IF($E5<>"",TEXT($E5,"HH"),"") -> 16 | BX5: 46198 | BY5: 2 | BZ5: =IF(B5<>"",VALUE(LEFT(B5)),"") -> 7 | CA5: {=IF($A5<>"",INDEX(LISTA!$M$2:$N$27,MATCH($BC5,LISTA!$N$2:$N$27,0),1),"")} -> 14 | CB5: =IF($A5<>"",MONTH(BU5),"") -> 6 | CC5: =IF($BX5<>"",MONTH(BX5),"") -> 6
A6: 46200.495 | B6: 7 - INSTALADA | C6: MASIVO RESIDENCIAL | D6: NAYELI | E6: 46202.458 | F6: PROCEDE | G6: 104896460 | H6: 88673676 | I6: JESSICA | J6: 954973060 | K6: DNI | L6: 80064841 | M6: LUIS ALBERTO DAVILA PAREDES | N6: 28883 | O6: PASCO | P6: 180101 | Z6: Huánuco | AQ6: DIOGENES | AR6: AMANDA | AS6: Luisalberto22davila79@gmail.com | AU6: 954973060 | AV6: 954973060 | AW6: AV. ANDRES FERNANDEZ GARRIDO URB. LAS GARDENIAS | AX6: 2 | AY6: NA | AZ6: -9.96498585, -76.245660663 | BA6: JR. SAN FAUSTO | BB6: HUPM008-S | BC6: HUANUCO | BD6: =IF(COUNTA(Q6:AP6)>0,INDEX(Q6:AP6,,max(IF(Q6:AP6<>"",COLUMN(Q6:AP6)))-16),"") -> Huánuco | BE6: FTTH | BF6: NO | BG6: ALTA NUEVA | BL6: 1 PLAY + L1MAX | BM6: Campaña Regular PRO | BN6: 110 | BO6: 500MBPS | BQ6: NO | BR6: Ninguno | BS6: 1 | BU6: =IF($A6<>"", DATE(YEAR($A6),MONTH($A6),DAY($A6)),"") -> 46200 | BV6: =IF($E6<>"",DATE(YEAR($E6),MONTH($E6),DAY($E6)),"") -> 46202 | BW6: =IF($E6<>"",TEXT($E6,"HH"),"") -> 11 | BX6: 46202 | BY6: 4 | BZ6: =IF(B6<>"",VALUE(LEFT(B6)),"") -> 7 | CA6: {=IF($A6<>"",INDEX(LISTA!$M$2:$N$27,MATCH($BC6,LISTA!$N$2:$N$27,0),1),"")} -> 12 | CB6: =IF($A6<>"",MONTH(BU6),"") -> 6 | CC6: =IF($BX6<>"",MONTH(BX6),"") -> 6
A7: 46196.508 | B7: 7 - INSTALADA | C7: MASIVO RESIDENCIAL | D7: NAYELI | E7: 46197.458 | F7: PAGO DE INSTALACION - CLIENTE ADELANTA VISITA 24/06 | G7: 104776353 | H7: 88565685 | I7: JUAN DIEGO | J7: 970168191 | K7: DNI | L7: 47430926 | M7: ELIZABETH CRISTINA BARRIENTOS OROSCO | N7: 33581 | O7: LIMA METROPOLITANA | P7: 150133 | AF7: Ate | AQ7: SEBASTIAN | AR7: GLORIA | AS7: eduorosco3@gmail.com | AU7: 970168191 | AV7: 999222641 | AW7: mz g lt 06 URBANIZACIÓN LAS PRADERAS DE PARIACHI tercera etapa | AX7: 2 | AY7: 0 | AZ7: -12.00525274093723, -76.8413549302252 | BA7: AV POSEIDON | BB7: LMAT142-F | BC7: LIMA METROPOLITANA | BD7: =IF(COUNTA(Q7:AP7)>0,INDEX(Q7:AP7,,max(IF(Q7:AP7<>"",COLUMN(Q7:AP7)))-16),"") -> Ate | BE7: FTTH | BF7: NO | BG7: ALTA NUEVA | BL7: 1 PLAY | BM7: Campaña Regular | BN7: 100 | BO7: 800MBPS | BP7: NO | BQ7: NO | BR7: Ninguno | BS7: 2 | BU7: =IF($A7<>"", DATE(YEAR($A7),MONTH($A7),DAY($A7)),"") -> 46196 | BV7: =IF($E7<>"",DATE(YEAR($E7),MONTH($E7),DAY($E7)),"") -> 46197 | BW7: =IF($E7<>"",TEXT($E7,"HH"),"") -> 11 | BX7: 46197 | BY7: 1 | BZ7: =IF(B7<>"",VALUE(LEFT(B7)),"") -> 7 | CA7: {=IF($A7<>"",INDEX(LISTA!$M$2:$N$27,MATCH($BC7,LISTA!$N$2:$N$27,0),1),"")} -> 1 | CB7: =IF($A7<>"",MONTH(BU7),"") -> 6 | CC7: =IF($BX7<>"",MONTH(BX7),"") -> 6
A8: 46179.52 | B8: 7 - INSTALADA | C8: MASIVO RESIDENCIAL | D8: NAYELI | E8: 46185.583 | F8: LYBTEL | G8: 104457724 | H8: 88271126 | I8: ROCIO | J8: 998357850 | K8: DNI | L8: 43729341 | M8: HUGO HERRERA NUÑEZ | N8: 31658 | O8: LIMA | P8: 150131 | AF8: Santiago de Surco | AQ8: HUGO | AR8: MARIA | AS8: jnunezo@hotmail.es | AU8: 997351175 | AV8: 997351175 | AW8: ayacucho 942 santiago de surco dto 402 | AX8: 4 | AY8: 402 | AZ8: -12.136189335877416, -76.99837869182522 | BA8: AV DOñA RAQUEL | BB8: LMSC293-F | BC8: LIMA METROPOLITANA | BD8: =IF(COUNTA(Q8:AP8)>0,INDEX(Q8:AP8,,max(IF(Q8:AP8<>"",COLUMN(Q8:AP8)))-16),"") -> Santiago de Surco | BE8: FTTH | BF8: NO | BG8: ALTA NUEVA | BL8: 2 PLAY + TV ESTANDAR | BM8: Campaña Regular | BN8: 170 | BO8: 400MBPS | BP8: NO | BQ8: NO | BR8: Ninguno | BS8: Ninguno | BU8: =IF($A8<>"", DATE(YEAR($A8),MONTH($A8),DAY($A8)),"") -> 46179 | BV8: =IF($E8<>"",DATE(YEAR($E8),MONTH($E8),DAY($E8)),"") -> 46185 | BW8: =IF($E8<>"",TEXT($E8,"HH"),"") -> 14 | BX8: 46185 | BY8: 1 | BZ8: =IF(B8<>"",VALUE(LEFT(B8)),"") -> 7 | CA8: {=IF($A8<>"",INDEX(LISTA!$M$2:$N$27,MATCH($BC8,LISTA!$N$2:$N$27,0),1),"")} -> 1 | CB8: =IF($A8<>"",MONTH(BU8),"") -> 6 | CC8: =IF($BX8<>"",MONTH(BX8),"") -> 6
A9: 46192.657 | B9: 7 - INSTALADA | C9: MASIVO RESIDENCIAL | D9: PAOLA | E9: 46193.458 | F9: SE MANDA A ANULAR SOT LOS DATOS DE DIRECCIÓN ES INCORRECTO/ CORREGIDO | G9: 104692164 | H9: 88475969 | I9: SAHIR | J9: 995048683 | K9: DNI | L9: 43379508 | M9: JULIO RAMON CHUNG GONZALES | N9: 31436 | O9: LIMA METROPOLITANA | P9: 150121 | AF9: Lince | AQ9: luis fernando | AR9: elvira marina | AS9: julianchungonzales@gmail.com | AU9: 995048683 | AV9: 995048683 | AW9: JIRON INCA GARCILASO DE LA VEGA 1874 URBANIZACION RISSO LINCE | AX9: 1 | AY9: 1 | AZ9: -12.084034, -77.040746 | BA9: av canebaro | BB9: LMLC077-F | BC9: LIMA METROPOLITANA | BD9: =IF(COUNTA(Q9:AP9)>0,INDEX(Q9:AP9,,max(IF(Q9:AP9<>"",COLUMN(Q9:AP9)))-16),"") -> Lince | BE9: FTTH | BF9: SI | BG9: ALTA NUEVA | BL9: 2PLAY + TELF | BM9: Campaña Regular | BN9: 94 | BO9: 400MBPS | BP9: NO | BQ9: SI | BR9: Ninguno | BS9: 1 | BU9: =IF($A9<>"", DATE(YEAR($A9),MONTH($A9),DAY($A9)),"") -> 46192 | BV9: =IF($E9<>"",DATE(YEAR($E9),MONTH($E9),DAY($E9)),"") -> 46193 | BW9: =IF($E9<>"",TEXT($E9,"HH"),"") -> 11 | BX9: 46194 | BY9: 1 | BZ9: =IF(B9<>"",VALUE(LEFT(B9)),"") -> 7 | CA9: {=IF($A9<>"",INDEX(LISTA!$M$2:$N$27,MATCH($BC9,LISTA!$N$2:$N$27,0),1),"")} -> 1 | CB9: =IF($A9<>"",MONTH(BU9),"") -> 6 | CC9: =IF($BX9<>"",MONTH(BX9),"") -> 6
A10: 46196.576 | B10: 7 - INSTALADA | C10: MASIVO RESIDENCIAL | D10: NAYELI | E10: 46199.583 | F10: PROCEDE, EDIFICIO HABILITADO | G10: 104780309 | H10: 88566260 | I10: ANTHONELLA | J10: 968906150 | K10: DNI | L10: 48294663 | M10: KEVIN JUSTIN GUERRA LÓPEZ | N10: 34087 | O10: LIMA METROPOLITANA | P10: 150117 | AF10: Surquillo | AQ10: OSCAR | AR10: MAXIMINA | AS10: kevin.04.gl@gmail.com | AU10: 968906150 | AV10: 968906150 | AW10: Av. Principal 915 Surquillo Edificio: VITTORIE | AX10: 9 | AY10: 901 | AZ10: -12.119644, -77.00413 | BA10: av principal | BB10: LMSQ089-S | BC10: LIMA METROPOLITANA | BD10: =IF(COUNTA(Q10:AP10)>0,INDEX(Q10:AP10,,max(IF(Q10:AP10<>"",COLUMN(Q10:AP10)))-16),"") -> Surquillo | BE10: FTTH | BF10: SI | BG10: ALTA NUEVA | BL10: 1 PLAY | BM10: Campaña Regular | BN10: 110 | BO10: 500MBPS | BP10: SI | BQ10: NO | BR10: Ninguno | BS10: Ninguno | BU10: =IF($A10<>"", DATE(YEAR($A10),MONTH($A10),DAY($A10)),"") -> 46196 | BV10: =IF($E10<>"",DATE(YEAR($E10),MONTH($E10),DAY($E10)),"") -> 46199 | BW10: =IF($E10<>"",TEXT($E10,"HH"),"") -> 14 | BX10: 46199 | BY10: 2 | BZ10: =IF(B10<>"",VALUE(LEFT(B10)),"") -> 7 | CA10: {=IF($A10<>"",INDEX(LISTA!$M$2:$N$27,MATCH($BC10,LISTA!$N$2:$N$27,0),1),"")} -> 1 | CB10: =IF($A10<>"",MONTH(BU10),"") -> 6 | CC10: =IF($BX10<>"",MONTH(BX10),"") -> 6
A11: 46197.502 | B11: 7 - INSTALADA | C11: MASIVO RESIDENCIAL | D11: NAYELI | E11: 46198.583 | F11: CONFIRMA VISITA | G11: 104805604 | H11: 88589466 | I11: JUAN DIEGO | J11: 944551713 | K11: DNI | L11: 42863482 | M11: MARCO ANTONIO BLAS ZUÑIGA | N11: 31111 | O11: LIMA METROPOLITANA | P11: 150113 | AF11: San Juan de Miraflores | AQ11: MANUEL | AR11: BLANCA | AS11: marcoantonioblaszuniga@gmail.com | AU11: 944 551 713 | AV11: 944 551 713 | AW11: Mz 90 lt 12 URB LOS BRILLANTES SAN JUAN DE MIRAFLORES LIMA | AX11: 2 | AY11: NA | AZ11: -12.144510048064456, -76.96690070477077 | BA11: AVENIDA CENTRAL CON PASAJE SANTA ROSA | BB11: LMJR114-F | BC11: LIMA METROPOLITANA | BD11: =IF(COUNTA(Q11:AP11)>0,INDEX(Q11:AP11,,max(IF(Q11:AP11<>"",COLUMN(Q11:AP11)))-16),"") -> San Juan de Miraflores | BE11: FTTH | BF11: SI | BG11: ALTA NUEVA | BL11: 2PLAY + TELF | BM11: Campaña Regular | BN11: 94 | BO11: 400MBPS | BP11: NO | BQ11: SI | BR11: Ninguno | BS11: 1 | BU11: =IF($A11<>"", DATE(YEAR($A11),MONTH($A11),DAY($A11)),"") -> 46197 | BV11: =IF($E11<>"",DATE(YEAR($E11),MONTH($E11),DAY($E11)),"") -> 46198 | BW11: =IF($E11<>"",TEXT($E11,"HH"),"") -> 14 | BX11: 46198 | BY11: 3 | BZ11: =IF(B11<>"",VALUE(LEFT(B11)),"") -> 7 | CA11: {=IF($A11<>"",INDEX(LISTA!$M$2:$N$27,MATCH($BC11,LISTA!$N$2:$N$27,0),1),"")} -> 1 | CB11: =IF($A11<>"",MONTH(BU11),"") -> 6 | CC11: =IF($BX11<>"",MONTH(BX11),"") -> 6
A12: 46198.601 | B12: 7 - INSTALADA | C12: MASIVO RESIDENCIAL | D12: NAYELI | E12: 46201.375 | F12: PROCEDE SE ENVIA ADELANTO 26/06 | G12: 104842396 | H12: 88622310 | I12: ANTHONELLA | J12: 959466891 | K12: DNI | L12: 75454838 | M12: ROCIO LESLY FIGUEROA RODRIGUEZ | N12: 35060 | O12: LIMA | P12: 150101 | W12: Callao | AQ12: TEODOSIO | AR12: BETTY | AS12: figeroa.air23@gmail.com | AU12: 959466891 | AV12: 976269839 | AW12: Albino Herrera 2da Etp. Mz.B1 Lt.20 - Callao | AX12: 3 | AY12: SIN | AZ12: -12.010193, -77.095981 | BA12: AV LOS DOMINICOS | BB12: LMCA009-S | BC12: CALLAO | BD12: =IF(COUNTA(Q12:AP12)>0,INDEX(Q12:AP12,,max(IF(Q12:AP12<>"",COLUMN(Q12:AP12)))-16),"") -> Callao | BE12: FTTH | BF12: NO | BG12: ALTA NUEVA | BL12: 1 PLAY | BM12: Campaña Regular | BN12: 89 | BO12: 400MBPS | BP12: SI | BQ12: NO | BR12: Ninguno | BS12: Ninguno | BU12: =IF($A12<>"", DATE(YEAR($A12),MONTH($A12),DAY($A12)),"") -> 46198 | BV12: =IF($E12<>"",DATE(YEAR($E12),MONTH($E12),DAY($E12)),"") -> 46201 | BW12: =IF($E12<>"",TEXT($E12,"HH"),"") -> 09 | BX12: 46201 | BY12: 1 | BZ12: =IF(B12<>"",VALUE(LEFT(B12)),"") -> 7 | CA12: {=IF($A12<>"",INDEX(LISTA!$M$2:$N$27,MATCH($BC12,LISTA!$N$2:$N$27,0),1),"")} -> 2 | CB12: =IF($A12<>"",MONTH(BU12),"") -> 6 | CC12: =IF($BX12<>"",MONTH(BX12),"") -> 6
A13: 46199.708 | B13: 7 - INSTALADA | C13: MASIVO RESIDENCIAL | D13: NAYELI | E13: 46202.458 | F13: PROCEDE | G13: 104878027 | H13: 88663022 | I13: GABRIEL | J13: 946215729 | K13: DNI | L13: 75416717 | M13: CRISTEL NICOLT LOPEZ ESPADA | N13: 38508 | O13: LIMA | P13: 140501 | AE13: Huaura | AQ13: HILMER | AR13: MARIA | AS13: Crisle.0506@gmail.com | AU13: 946215729 | AV13: 946215729 | AW13: FRANSISCO ROSAS 346 | AX13: 3 | AY13: 1 | AZ13: -11.104527221283575, -77.60735781101647 | BA13: AL COSTADO DE FERRETERIA NANCY | BB13: LMHU018-S | BC13: LIMA | BD13: =IF(COUNTA(Q13:AP13)>0,INDEX(Q13:AP13,,max(IF(Q13:AP13<>"",COLUMN(Q13:AP13)))-16),"") -> Huaura | BE13: FTTH | BF13: NO | BG13: ALTA NUEVA | BL13: 1 PLAY | BM13: Campaña Regular | BN13: 69 | BO13: 200MBPS | BP13: NO | BQ13: NO | BR13: Ninguno | BS13: Ninguno | BU13: =IF($A13<>"", DATE(YEAR($A13),MONTH($A13),DAY($A13)),"") -> 46199 | BV13: =IF($E13<>"",DATE(YEAR($E13),MONTH($E13),DAY($E13)),"") -> 46202 | BW13: =IF($E13<>"",TEXT($E13,"HH"),"") -> 11 | BX13: 46202 | BY13: 1 | BZ13: =IF(B13<>"",VALUE(LEFT(B13)),"") -> 7 | CA13: {=IF($A13<>"",INDEX(LISTA!$M$2:$N$27,MATCH($BC13,LISTA!$N$2:$N$27,0),1),"")} -> 3 | CB13: =IF($A13<>"",MONTH(BU13),"") -> 6 | CC13: =IF($BX13<>"",MONTH(BX13),"") -> 6
A14: 46191.528 | B14: 7 - INSTALADA | C14: MASIVO RESIDENCIAL | D14: NAYELI | E14: 46200.458 | F14: PROCEDE FULL CLARO | G14: 104645330 | H14: 88434668 | I14: JESSICA | J14: 952589629 | K14: DNI | L14: 10811695 | M14: JENNY PAOLY ROJAS BENITO | N14: 28323 | O14: LIMA | P14: 140125 | AF14: Santiago de Surco | AQ14: GUSTAVO | AR14: MARGARITA | AS14: jainy31@hotmail.com | AU14: 953735960 | AV14: 953735960 | AW14: ASENTAMIENTO HUMANO LOS VIÑEDOS DE SURCO MZ H LT 35 | AX14: 3 | AY14: NA | AZ14: -12.162537454 -76.9885167909999 | BA14: Losa deportiva Los viñedos | BB14: LMSC325-F | BC14: LIMA METROPOLITANA | BD14: =IF(COUNTA(Q14:AP14)>0,INDEX(Q14:AP14,,max(IF(Q14:AP14<>"",COLUMN(Q14:AP14)))-16),"") -> Santiago de Surco | BE14: FTTH | BF14: SI | BG14: ALTA NUEVA | BL14: 2 PLAY + TV ESTANDAR | BM14: Campaña Regular PRO | BN14: 170 | BO14: 400MBPS | BP14: SI | BQ14: NO | BR14: 2 | BS14: 1 | BU14: =IF($A14<>"", DATE(YEAR($A14),MONTH($A14),DAY($A14)),"") -> 46191 | BV14: =IF($E14<>"",DATE(YEAR($E14),MONTH($E14),DAY($E14)),"") -> 46200 | BW14: =IF($E14<>"",TEXT($E14,"HH"),"") -> 11 | BX14: 46202 | BY14: 2 | BZ14: =IF(B14<>"",VALUE(LEFT(B14)),"") -> 7 | CA14: {=IF($A14<>"",INDEX(LISTA!$M$2:$N$27,MATCH($BC14,LISTA!$N$2:$N$27,0),1),"")} -> 1 | CB14: =IF($A14<>"",MONTH(BU14),"") -> 6 | CC14: =IF($BX14<>"",MONTH(BX14),"") -> 6
A15: 46190.379 | B15: 7 - INSTALADA | C15: MASIVO RESIDENCIAL | D15: NAYELI | E15: 46191.583 | F15: PROCEDE/ EDIFICIO HABILITADO | G15: 104605460 | H15: 88405389 | I15: JESSICA | J15: 987579907 | K15: DNI | L15: 70350550 | M15: CLAUDIA ISABEL GIL VIDAL | N15: 33362 | O15: LIMA | P15: 140115 | AF15: Miraflores | AQ15: FERNANDO HUMBERTO | AR15: IRMA BETTY | AS15: cgilvidal@gmail.com | AU15: 987579907 | AV15: 987579907 | AW15: AVENIDA PASEO DE LA REPUBLICA 6373 URBANIZACION SAN ANTONIO | AX15: 16 | AY15: 1601 | AZ15: -12.132422, -77.021475 | BA15: VIA EXPRESA LUIS FERNAN BEDOYA REYES | BB15: LMMF083 | BC15: LIMA METROPOLITANA | BD15: =IF(COUNTA(Q15:AP15)>0,INDEX(Q15:AP15,,max(IF(Q15:AP15<>"",COLUMN(Q15:AP15)))-16),"") -> Miraflores | BE15: HFC | BF15: SI | BG15: ALTA NUEVA | BL15: 1 PLAY + L1MAX | BM15: Campaña Regular PRO | BN15: 110 | BO15: 500MBPS | BP15: SI | BQ15: NO | BR15: Ninguno | BS15: Ninguno | BU15: =IF($A15<>"", DATE(YEAR($A15),MONTH($A15),DAY($A15)),"") -> 46190 | BV15: =IF($E15<>"",DATE(YEAR($E15),MONTH($E15),DAY($E15)),"") -> 46191 | BW15: =IF($E15<>"",TEXT($E15,"HH"),"") -> 14 | BX15: 46191 | BY15: 1 | BZ15: =IF(B15<>"",VALUE(LEFT(B15)),"") -> 7 | CA15: {=IF($A15<>"",INDEX(LISTA!$M$2:$N$27,MATCH($BC15,LISTA!$N$2:$N$27,0),1),"")} -> 1 | CB15: =IF($A15<>"",MONTH(BU15),"") -> 6 | CC15: =IF($BX15<>"",MONTH(BX15),"") -> 6
A16: 46190.494 | B16: 7 - INSTALADA | C16: MASIVO RESIDENCIAL | D16: PAOLA | E16: 46193.458 | F16: LLAMAR 12:30 | G16: 104649549 | H16: 88437602 | I16: PAOLA | J16: 915992860 | K16: DNI | L16: 40537157 | M16: JOHANA MEDALITH MELENDEZ CHINGA | N16: 29369 | O16: LIMA | P16: 140101 | AE16: Huaura | AQ16: JULIO | AR16: ELENA | AS16: RICHARDTJ_3@HOTMAIL.COM | AU16: 963877220 | AV16: 915992860 | AW16: Urb Martir Jose Olaya mz g lote 12 | AX16: 2 | AY16: NA | AZ16: -11.09480528124759, -77.62592378552375 | BA16: JR 28 OCTUBRE | BB16: LMCQ002 | BC16: LIMA | BD16: =IF(COUNTA(Q16:AP16)>0,INDEX(Q16:AP16,,max(IF(Q16:AP16<>"",COLUMN(Q16:AP16)))-16),"") -> Huaura | BE16: HFC | BF16: SI | BG16: ALTA NUEVA | BL16: 1 PLAY | BM16: Campaña Regular | BN16: 110 | BO16: 500MBPS | BP16: NO | BQ16: NO | BR16: 1 | BS16: 1 | BU16: =IF($A16<>"", DATE(YEAR($A16),MONTH($A16),DAY($A16)),"") -> 46190 | BV16: =IF($E16<>"",DATE(YEAR($E16),MONTH($E16),DAY($E16)),"") -> 46193 | BW16: =IF($E16<>"",TEXT($E16,"HH"),"") -> 11 | BX16: 46192 | BY16: 1 | BZ16: =IF(B16<>"",VALUE(LEFT(B16)),"") -> 7 | CA16: {=IF($A16<>"",INDEX(LISTA!$M$2:$N$27,MATCH($BC16,LISTA!$N$2:$N$27,0),1),"")} -> 3 | CB16: =IF($A16<>"",MONTH(BU16),"") -> 6 | CC16: =IF($BX16<>"",MONTH(BX16),"") -> 6
A17: 46184.543 | B17: 7 - INSTALADA | C17: MASIVO RESIDENCIAL | D17: NAYELI | E17: 46185.667 | F17: LYBTEL | G17: 104449975 | H17: 88267394 | I17: ROCIO | J17: 985871277 | K17: DNI | L17: 43252312 | M17: SUSAN IVONNE HEREDIA CORDOVA | N17: 31371 | O17: JUNIN | P17: 110101 | AF17: San Martín de Porres | AQ17: luis | AR17: lucila | AS17: Gabycina@hotmail.com | AU17: 985871277 | AV17: 985871277 | AW17: Urb.San german Jr Ávila Godoy 657 | AX17: 4 | AY17: 1 | AZ17: -12.015793, -77.071245 | BA17: ingreso es por el jardín inicial Germancito | BB17: LMMP233-F | BC17: LIMA METROPOLITANA | BD17: =IF(COUNTA(Q17:AP17)>0,INDEX(Q17:AP17,,max(IF(Q17:AP17<>"",COLUMN(Q17:AP17)))-16),"") -> San Martín de Porres | BE17: FTTH | BF17: SI | BG17: ALTA NUEVA | BL17: 1 PLAY | BM17: Campaña Regular | BN17: 110 | BO17: 500MBPS | BP17: SI | BQ17: NO | BR17: Ninguno | BS17: 1 | BU17: =IF($A17<>"", DATE(YEAR($A17),MONTH($A17),DAY($A17)),"") -> 46184 | BV17: =IF($E17<>"",DATE(YEAR($E17),MONTH($E17),DAY($E17)),"") -> 46185 | BW17: =IF($E17<>"",TEXT($E17,"HH"),"") -> 16 | BX17: 46186 | BY17: 1 | BZ17: =IF(B17<>"",VALUE(LEFT(B17)),"") -> 7 | CA17: {=IF($A17<>"",INDEX(LISTA!$M$2:$N$27,MATCH($BC17,LISTA!$N$2:$N$27,0),1),"")} -> 1 | CB17: =IF($A17<>"",MONTH(BU17),"") -> 6 | CC17: =IF($BX17<>"",MONTH(BX17),"") -> 6
A18: 46196.789 | B18: 7 - INSTALADA | C18: MASIVO RESIDENCIAL | D18: PAOLA | E18: 46197.458 | F18: PROCEDE | G18: 104793755 | H18: 88574820 | I18: GABRIEL | J18: 959579554 | K18: DNI | L18: 72000616 | M18: KARELIA BEATRIZ GAVILAN PURILLA | N18: 33908 | O18: ICA | P18: 110101 | AA18: Ica | AQ18: Javier | AR18: Nancy | AS18: kareliagp.gp@gmail.com | AU18: 959579554 | AV18: 959579554 | AW18: Av pachacutec yupanqui 986 parcona , ica , ica | AX18: 1 | AY18: S/I | AZ18: -14.04519699, -75.70771398 | BA18: CADIMOTORS/MOTO REPUESTOS Y TALLER | BB18: ICPN008 | BC18: ICA | BD18: =IF(COUNTA(Q18:AP18)>0,INDEX(Q18:AP18,,max(IF(Q18:AP18<>"",COLUMN(Q18:AP18)))-16),"") -> Ica | BE18: HFC | BF18: NO | BG18: ALTA NUEVA | BL18: 1 PLAY | BM18: Campaña Promo Mediana | BN18: 89 | BO18: 400MBPS | BP18: NO | BQ18: NO | BR18: Ninguno | BS18: Ninguno | BU18: =IF($A18<>"", DATE(YEAR($A18),MONTH($A18),DAY($A18)),"") -> 46196 | BV18: =IF($E18<>"",DATE(YEAR($E18),MONTH($E18),DAY($E18)),"") -> 46197 | BW18: =IF($E18<>"",TEXT($E18,"HH"),"") -> 11 | BX18: 46197 | BY18: 2 | BZ18: =IF(B18<>"",VALUE(LEFT(B18)),"") -> 7 | CA18: {=IF($A18<>"",INDEX(LISTA!$M$2:$N$27,MATCH($BC18,LISTA!$N$2:$N$27,0),1),"")} -> 13 | CB18: =IF($A18<>"",MONTH(BU18),"") -> 6 | CC18: =IF($BX18<>"",MONTH(BX18),"") -> 6
A19: 46190.47 | B19: 7 - INSTALADA | C19: MASIVO RESIDENCIAL | D19: NAYELI | E19: 46198.375 | F19: CONFIRMA VISITA /Rechazado por mala oferta - Campo - SE MANDO A LEVANTAR LA SOT | G19: 104610174 | H19: 88407642 | I19: JESSICA | J19: 993793126 | K19: DNI | L19: 06063811 | M19: ALEJANDRO ENRIQUE PALOMINO LEON | N19: 21472 | O19: JUNIN | P19: 110101 | AF19: Rimac | AQ19: ADALBERTO | AR19: OLGA | AS19: abogadopalomino@hotmail.com | AU19: 993793126 | AV19: 993793126 | AW19: PASAJE CENTRAL 123 | AX19: 4 | AY19: 401 | AZ19: -12.030148683042182, -77.04209244735932 | BA19: NEGOCIOS Y SERVICIOS D. ALCANTARA | BB19: LMRC044-F | BC19: LIMA METROPOLITANA | BD19: =IF(COUNTA(Q19:AP19)>0,INDEX(Q19:AP19,,max(IF(Q19:AP19<>"",COLUMN(Q19:AP19)))-16),"") -> Rimac | BE19: FTTH | BF19: SI | BG19: ALTA NUEVA | BL19: 1 PLAY + L1MAX | BM19: Campaña Regular PRO | BN19: 110 | BO19: 500MBPS | BP19: SI | BQ19: NO | BR19: Ninguno | BS19: 1 | BU19: =IF($A19<>"", DATE(YEAR($A19),MONTH($A19),DAY($A19)),"") -> 46190 | BV19: =IF($E19<>"",DATE(YEAR($E19),MONTH($E19),DAY($E19)),"") -> 46198 | BW19: =IF($E19<>"",TEXT($E19,"HH"),"") -> 09 | BX19: 46198 | BY19: 1 | BZ19: =IF(B19<>"",VALUE(LEFT(B19)),"") -> 7 | CA19: {=IF($A19<>"",INDEX(LISTA!$M$2:$N$27,MATCH($BC19,LISTA!$N$2:$N$27,0),1),"")} -> 1 | CB19: =IF($A19<>"",MONTH(BU19),"") -> 6 | CC19: =IF($BX19<>"",MONTH(BX19),"") -> 6
A20: 46200.749 | B20: 7 - INSTALADA | C20: MASIVO RESIDENCIAL | D20: NAYELI | E20: 46203.375 | F20: PROCEDE | G20: 104909457 | H20: 88679217 | I20: GABRIEL | J20: 997867217 | K20: DNI | L20: 08450266 | M20: NORMA MONICA, PACHECHO AGUILAR | N20: 24235 | O20: CUSCO | P20: 080101 | AF20: San Martín de Porres | AQ20: CARLOS | AR20: ANA | AS20: monikapachecho840@gmail.com | AU20: 997867217 | AV20: 997867217 | AW20: AV UNIVERSITARIA 621 URB SEÑOR DE CONDEVILLA | AX20: 2 | AY20: S/I | AZ20: -12.020495, -77.075867 | BA20: JR LAS AMERICAS | BB20: LMMP059-S | BC20: LIMA METROPOLITANA | BD20: =IF(COUNTA(Q20:AP20)>0,INDEX(Q20:AP20,,max(IF(Q20:AP20<>"",COLUMN(Q20:AP20)))-16),"") -> San Martín de Porres | BE20: FTTH | BF20: NO | BG20: ALTA NUEVA | BL20: 3 PLAY + TV ESTANDAR | BM20: Campaña Regular | BN20: 155 | BO20: 200MBPS | BP20: NO | BQ20: NO | BR20: Ninguno | BS20: Ninguno | BU20: =IF($A20<>"", DATE(YEAR($A20),MONTH($A20),DAY($A20)),"") -> 46200 | BV20: =IF($E20<>"",DATE(YEAR($E20),MONTH($E20),DAY($E20)),"") -> 46203 | BW20: =IF($E20<>"",TEXT($E20,"HH"),"") -> 09 | BX20: 46203 | BY20: 1 | BZ20: =IF(B20<>"",VALUE(LEFT(B20)),"") -> 7 | CA20: {=IF($A20<>"",INDEX(LISTA!$M$2:$N$27,MATCH($BC20,LISTA!$N$2:$N$27,0),1),"")} -> 1 | CB20: =IF($A20<>"",MONTH(BU20),"") -> 6 | CC20: =IF($BX20<>"",MONTH(BX20),"") -> 6
A21: 46193.5 | B21: 7 - INSTALADA | C21: MASIVO RESIDENCIAL | D21: PAOLA | E21: 46195.458 | F21: no coincide | G21: 104449975 | H21: 88480813 | I21: ANGHELL | J21: 977370315 | K21: DNI | L21: 75081907 | M21: MANUEL ALDAYR MONTUFAR LAIME | N21: 37189 | O21: CUSCO | P21: 07081 | X21: Espinar | AQ21: MANUEL | AR21: FILOMENA | AS21: AQPFEX1@GMAIL.COM | AU21: 977370315 | AV21: 977370315 | AW21: ubr huarcanto mz a1 lt 17 | AX21: 2 | AY21: 2A | AZ21: -14.799989, -71.411517 | BA21: calle nueva baja | BB21: CZES020-F | BC21: CUSCO | BD21: =IF(COUNTA(Q21:AP21)>0,INDEX(Q21:AP21,,max(IF(Q21:AP21<>"",COLUMN(Q21:AP21)))-16),"") -> Espinar | BE21: FTTH | BF21: NO | BG21: ALTA NUEVA | BL21: 2PLAY + TELF | BM21: Campaña Relámpago | BN21: 94 | BO21: 400MBPS | BP21: NO | BQ21: SI | BR21: Ninguno | BS21: Ninguno | BU21: =IF($A21<>"", DATE(YEAR($A21),MONTH($A21),DAY($A21)),"") -> 46193 | BV21: =IF($E21<>"",DATE(YEAR($E21),MONTH($E21),DAY($E21)),"") -> 46195 | BW21: =IF($E21<>"",TEXT($E21,"HH"),"") -> 11 | BX21: 46194 | BY21: 2 | BZ21: =IF(B21<>"",VALUE(LEFT(B21)),"") -> 7 | CA21: {=IF($A21<>"",INDEX(LISTA!$M$2:$N$27,MATCH($BC21,LISTA!$N$2:$N$27,0),1),"")} -> 10 | CB21: =IF($A21<>"",MONTH(BU21),"") -> 6 | CC21: =IF($BX21<>"",MONTH(BX21),"") -> 6
A22: 46199.594 | B22: 7 - INSTALADA | C22: MASIVO RESIDENCIAL | D22: NAYELI | E22: 46201.458 | F22: CL QUIERE INSTALACION PARA EL LUNES | G22: 104872550 | H22: 88659360 | I22: JESSICA | J22: 959385387 | K22: DNI | L22: 40494768 | M22: TEODORO SAICO SUCLLE | N22: 28834 | O22: CUSCO | P22: 070801 | T22: Arequipa | AQ22: NOLASCO | AR22: PAULINA | AS22: Teosaico@hotmail.com | AU22: 959385387 | AV22: 959385387 | AW22: CALLE CAHUIDE 315 URB. LA LIBERTAD | AX22: 2 | AY22: NA | AZ22: -16.37709499, -71.56237894 | BA22: CALLE MIGUEL GRAU | BB22: AQCC004-S | BC22: AREQUIPA | BD22: =IF(COUNTA(Q22:AP22)>0,INDEX(Q22:AP22,,max(IF(Q22:AP22<>"",COLUMN(Q22:AP22)))-16),"") -> Arequipa | BE22: FTTH | BF22: SI | BG22: ALTA NUEVA | BL22: 1 PLAY + L1MAX | BM22: Campaña Regular PRO | BN22: 110 | BO22: 500MBPS | BP22: SI | BQ22: NO | BR22: Ninguno | BS22: 1 | BU22: =IF($A22<>"", DATE(YEAR($A22),MONTH($A22),DAY($A22)),"") -> 46199 | BV22: =IF($E22<>"",DATE(YEAR($E22),MONTH($E22),DAY($E22)),"") -> 46201 | BW22: =IF($E22<>"",TEXT($E22,"HH"),"") -> 11 | BX22: 46201 | BY22: 2 | BZ22: =IF(B22<>"",VALUE(LEFT(B22)),"") -> 7 | CA22: {=IF($A22<>"",INDEX(LISTA!$M$2:$N$27,MATCH($BC22,LISTA!$N$2:$N$27,0),1),"")} -> 7 | CB22: =IF($A22<>"",MONTH(BU22),"") -> 6 | CC22: =IF($BX22<>"",MONTH(BX22),"") -> 6
A23: 46193.413 | B23: 7 - INSTALADA | C23: MASIVO RESIDENCIAL | D23: PAOLA | E23: 46196.458 | F23: PROCEDE ERROR EN DIRECCION | G23: 104714476 | H23: 88484483 | I23: YESSENIA | J23: 937542448 | K23: DNI | L23: 74602108 | M23: BRYAN ALFREDO MOREANO OBANDO | N23: 35956 | O23: CALLAO | P23: 070103 | AF23: La Victoria | AQ23: ALFREDO | AR23: MARITA | AS23: bmoreanoo@gmail.com | AU23: 937542448 | AV23: 937542448 | AW23: Jr. Carlos Gutiérrez Noriega 480 | AX23: 5 | AY23: 504 | AZ23: -12.07782297,-77.01624108 | BA23: JR CARLOS LOPEZ ALDANA | BB23: LMLV009-S | BC23: LIMA METROPOLITANA | BD23: =IF(COUNTA(Q23:AP23)>0,INDEX(Q23:AP23,,max(IF(Q23:AP23<>"",COLUMN(Q23:AP23)))-16),"") -> La Victoria | BE23: FTTH | BF23: NO | BG23: ALTA NUEVA | BL23: 1 PLAY | BM23: Campaña Promo Mediana | BN23: 89 | BO23: 400MBPS | BP23: NO | BQ23: NO | BR23: Ninguno | BS23: 1 | BU23: =IF($A23<>"", DATE(YEAR($A23),MONTH($A23),DAY($A23)),"") -> 46193 | BV23: =IF($E23<>"",DATE(YEAR($E23),MONTH($E23),DAY($E23)),"") -> 46196 | BW23: =IF($E23<>"",TEXT($E23,"HH"),"") -> 11 | BX23: 46196 | BY23: 1 | BZ23: =IF(B23<>"",VALUE(LEFT(B23)),"") -> 7 | CA23: {=IF($A23<>"",INDEX(LISTA!$M$2:$N$27,MATCH($BC23,LISTA!$N$2:$N$27,0),1),"")} -> 1 | CB23: =IF($A23<>"",MONTH(BU23),"") -> 6 | CC23: =IF($BX23<>"",MONTH(BX23),"") -> 6
A24: 46198.728 | B24: 7 - INSTALADA | C24: MASIVO RESIDENCIAL | D24: NAYELI | E24: 46200.5 | F24: CL CONFIRMA VISITA | G24: 104849431 | H24: 88626343 | I24: JESSICA | J24: 974629301 | K24: DNI | L24: 45346787 | M24: LEWIS RICHARD CORDOVA HUAMAN | N24: 32425 | O24: CAJAMARCA | P24: 061102 | AF24: Comas | AQ24: HECTOR | AR24: ERNESTINA | AS24: lrcordovah88@gmail.com | AU24: 974629301 | AV24: 974629301 | AW24: AV MICAELA BASTIDAS Mz G Lt - BLOCK 6 ( AV. MICAELA BASTIDAS S/N BLOCK 06 - TORRE A ETAPA 7 MZ. G ) Edificio: VISTA SOL - SOL DE COLLIQUE - TORRE A - BLOCK 06 | AX24: 10 | AY24: 1008 | AZ24: -11.927046, -77.059691 | BA24: AV. LOS CHASQUIS | BB24: LMCO181 | BC24: LIMA METROPOLITANA | BD24: =IF(COUNTA(Q24:AP24)>0,INDEX(Q24:AP24,,max(IF(Q24:AP24<>"",COLUMN(Q24:AP24)))-16),"") -> Comas | BE24: HFC | BF24: SI | BG24: ALTA NUEVA | BL24: 2 PLAY + TV ESTANDAR | BM24: Campaña Regular PRO | BN24: 170 | BO24: 400MBPS | BP24: SI | BQ24: NO | BR24: 2 | BS24: Ninguno | BU24: =IF($A24<>"", DATE(YEAR($A24),MONTH($A24),DAY($A24)),"") -> 46198 | BV24: =IF($E24<>"",DATE(YEAR($E24),MONTH($E24),DAY($E24)),"") -> 46200 | BW24: =IF($E24<>"",TEXT($E24,"HH"),"") -> 12 | BX24: 46200 | BY24: 1 | BZ24: =IF(B24<>"",VALUE(LEFT(B24)),"") -> 7 | CA24: {=IF($A24<>"",INDEX(LISTA!$M$2:$N$27,MATCH($BC24,LISTA!$N$2:$N$27,0),1),"")} -> 1 | CB24: =IF($A24<>"",MONTH(BU24),"") -> 6 | CC24: =IF($BX24<>"",MONTH(BX24),"") -> 6
A25: 46200.619 | B25: 7 - INSTALADA | C25: MASIVO RESIDENCIAL | D25: NAYELI | E25: 46202.458 | F25: PROCEDE | G25: 104901334 | H25: 88675788 | I25: JESSICA | J25: 998420484 | K25: DNI | L25: 32221145 | M25: RUSBEL MANUEL OQUEÑA PASTOR | N25: 27314 | O25: ANCASH | P25: 020601 | AF25: Comas | AQ25: MANUEL | AR25: HISABEL | AS25: roquenap@gmail.com | AU25: 998420484 | AV25: 998420484 | AW25: CALLE JOSE BERNARDO ALCEDO 370 URB. COLLIQUE | AX25: 3 | AY25: 302 | AZ25: -11.91581521571454, -77.02561845492386 | BA25: CALLE CHICLAYO | BB25: LMCO226-F | BC25: LIMA METROPOLITANA | BD25: =IF(COUNTA(Q25:AP25)>0,INDEX(Q25:AP25,,max(IF(Q25:AP25<>"",COLUMN(Q25:AP25)))-16),"") -> Comas | BE25: FTTH | BF25: NO | BG25: ALTA NUEVA | BL25: 1 PLAY | BM25: Campaña Promo Mediana | BN25: 89 | BO25: 400MBPS | BP25: NO | BQ25: NO | BR25: Ninguno | BS25: 1 | BU25: =IF($A25<>"", DATE(YEAR($A25),MONTH($A25),DAY($A25)),"") -> 46200 | BV25: =IF($E25<>"",DATE(YEAR($E25),MONTH($E25),DAY($E25)),"") -> 46202 | BW25: =IF($E25<>"",TEXT($E25,"HH"),"") -> 11 | BX25: 46202 | BY25: 3 | BZ25: =IF(B25<>"",VALUE(LEFT(B25)),"") -> 7 | CA25: {=IF($A25<>"",INDEX(LISTA!$M$2:$N$27,MATCH($BC25,LISTA!$N$2:$N$27,0),1),"")} -> 1 | CB25: =IF($A25<>"",MONTH(BU25),"") -> 6 | CC25: =IF($BX25<>"",MONTH(BX25),"") -> 6
A26: 46195.509 | B26: 7 - INSTALADA | C26: MASIVO RESIDENCIAL | D26: NAYELI | E26: 46196.458 | F26: PROCEDE AXB | G26: 104742955 | H26: 88519977 | I26: JESSICA | J26: 935195970 | K26: DNI | L26: 42520693 | M26: MARCO ANTONIO JAMANCA ESPINOZA | N26: 30888 | O26: ANCASH | P26: 020101 | R26: Huaraz | AQ26: DIONICIO | AR26: EUGENIA MARCELA | AS26: Marcojmanca@gmail.com | AU26: 935195970 | AV26: 935195970 | AW26: PS. SANTO DOMINGO 120 | AX26: 3 | AY26: 1 | AZ26: -9.508119659146413, -77.5320333439741 | BA26: JIRON INDUSTRIAL | BB26: HZIN044-F | BC26: ANCASH | BD26: =IF(COUNTA(Q26:AP26)>0,INDEX(Q26:AP26,,max(IF(Q26:AP26<>"",COLUMN(Q26:AP26)))-16),"") -> Huaraz | BE26: FTTH | BF26: NO | BG26: ALTA NUEVA | BL26: 1 PLAY | BM26: Campaña Regular PRO | BN26: 110 | BO26: 500MBPS | BP26: SI | BQ26: NO | BR26: Ninguno | BS26: 1 | BU26: =IF($A26<>"", DATE(YEAR($A26),MONTH($A26),DAY($A26)),"") -> 46195 | BV26: =IF($E26<>"",DATE(YEAR($E26),MONTH($E26),DAY($E26)),"") -> 46196 | BW26: =IF($E26<>"",TEXT($E26,"HH"),"") -> 11 | BX26: 46196 | BY26: 2 | BZ26: =IF(B26<>"",VALUE(LEFT(B26)),"") -> 7 | CA26: {=IF($A26<>"",INDEX(LISTA!$M$2:$N$27,MATCH($BC26,LISTA!$N$2:$N$27,0),1),"")} -> 5 | CB26: =IF($A26<>"",MONTH(BU26),"") -> 6 | CC26: =IF($BX26<>"",MONTH(BX26),"") -> 6
A27: 46192.698 | B27: 7 - INSTALADA | C27: MASIVO RESIDENCIAL | D27: PAOLA | E27: 46200.458 | F27: INSTALACION A MEDIAS - RESERVA TERMINARAN EL 28/06 POR DECOS, CONFIRMADO CON CLIENTE. | G27: 104867348 | H27: 88655700 | I27: JULIANA | J27: 978345537 | K27: DNI | L27: 76586680 | M27: ERICK ABRAHAM HIGINIO SOTELO | N27: 36140 | O27: LIMA METROPOLITANA | P27: 150128 | AF27: Comas | AQ27: ABRAHAM | AR27: LUZ | AS27: ERICK_1199@HOTMAIL.COM | AU27: 978 345 537 | AV27: 978 345 537 | AW27: DIRECCION: MZ G2 LOTE 30 URB. EL ALAMO 2DA ETAPA, COMAS. | AX27: 2 | AY27: 1 | AZ27: -11.924353, -77.063183 | BA27: AV. MICAELA CON AV. TRAPICHE. | BB27: LMCO023 | BC27: LIMA METROPOLITANA | BD27: =IF(COUNTA(Q27:AP27)>0,INDEX(Q27:AP27,,max(IF(Q27:AP27<>"",COLUMN(Q27:AP27)))-16),"") -> Comas | BE27: HFC | BF27: SI | BG27: ALTA NUEVA | BL27: 2 PLAY + TV ESTANDAR | BM27: Campaña Regular | BN27: 170 | BO27: 400MBPS | BP27: SI | BQ27: NO | BR27: 2 | BS27: Ninguno | BU27: =IF($A27<>"", DATE(YEAR($A27),MONTH($A27),DAY($A27)),"") -> 46192 | BV27: =IF($E27<>"",DATE(YEAR($E27),MONTH($E27),DAY($E27)),"") -> 46200 | BW27: =IF($E27<>"",TEXT($E27,"HH"),"") -> 11 | BX27: 46203 | BY27: 2 | BZ27: =IF(B27<>"",VALUE(LEFT(B27)),"") -> 7 | CA27: {=IF($A27<>"",INDEX(LISTA!$M$2:$N$27,MATCH($BC27,LISTA!$N$2:$N$27,0),1),"")} -> 1 | CB27: =IF($A27<>"",MONTH(BU27),"") -> 6 | CC27: =IF($BX27<>"",MONTH(BX27),"") -> 6
A28: 46198.753 | B28: 7 - INSTALADA | C28: MASIVO RESIDENCIAL | D28: NAYELI | E28: 46203.375 | F28: PENDIENTE CULMINAR INSTALACION A LAS 3PM | G28: 104850593 | H28: 88626803 | I28: GABRIEL | J28: 923619505 | K28: DNI | L28: 47883104 | M28: MINES BALTIERREZ, FLOR STEFANY | N28: 34151 | O28: LIMA METROPOLITANA | P28: 150113 | AF28: Carabayllo | AQ28: RAFAEL | AR28: FLOR | AS28: stefmines2@gmail.com | AU28: 923619505 | AV28: 923619505 | AW28: JIRON 9 DE OCTUBRE 501 CARABAYLLO | AX28: 1 | AY28: S/I | AZ28: -11.886848358,-77.020306622 | BA28: A 1 CDRA DE HABLA BROSTER | BB28: LMBY014-S | BC28: LIMA METROPOLITANA | BD28: =IF(COUNTA(Q28:AP28)>0,INDEX(Q28:AP28,,max(IF(Q28:AP28<>"",COLUMN(Q28:AP28)))-16),"") -> Carabayllo | BE28: FTTH | BF28: NO | BG28: ALTA NUEVA | BL28: 1 PLAY | BM28: Campaña Promo Mediana | BN28: 89 | BO28: 400MBPS | BP28: NO | BQ28: NO | BR28: Ninguno | BS28: Ninguno | BU28: =IF($A28<>"", DATE(YEAR($A28),MONTH($A28),DAY($A28)),"") -> 46198 | BV28: =IF($E28<>"",DATE(YEAR($E28),MONTH($E28),DAY($E28)),"") -> 46203 | BW28: =IF($E28<>"",TEXT($E28,"HH"),"") -> 09 | BX28: 46203 | BY28: 3 | BZ28: =IF(B28<>"",VALUE(LEFT(B28)),"") -> 7 | CA28: {=IF($A28<>"",INDEX(LISTA!$M$2:$N$27,MATCH($BC28,LISTA!$N$2:$N$27,0),1),"")} -> 1 | CB28: =IF($A28<>"",MONTH(BU28),"") -> 6 | CC28: =IF($BX28<>"",MONTH(BX28),"") -> 6
A29: 46192.563 | B29: 5 - CTO - EXCEDE METRAJE | C29: MASIVO RESIDENCIAL | D29: PAOLA | E29: 46196.542 | F29: SE ENVIA CORREO PARA VALIDAR COBERTURA. SI SE PUEDE JALAR | G29: 104679491 | H29: 88466519 | I29: ANTHONELLA | J29: 957120462 | K29: DNI | L29: 71493074 | M29: ALIS MERCEDES FLORES | N29: 35028 | O29: LA LIBERTAD | P29: 130901 | AC29: Sánchez Carrión | AQ29: AGUSTIN | AR29: VENANCIA | AS29: alismercedesflores@gmail.com | AU29: 957120462 | AV29: 957120462 | AW29: JR ALFONZO HUGARTE 131 HUAMACHUCO | AX29: 3 | AY29: CASA | AZ29: -7.812432448, -78.050758315 | BA29: CRUCE CON JR TAFUR | BB29: LLHM003-F | BC29: LA LIBERTAD | BD29: =IF(COUNTA(Q29:AP29)>0,INDEX(Q29:AP29,,max(IF(Q29:AP29<>"",COLUMN(Q29:AP29)))-16),"") -> Sánchez Carrión | BE29: FTTH | BF29: NO | BG29: ALTA NUEVA | BL29: 1 PLAY | BM29: Campaña Regular | BN29: 89 | BO29: 400MBPS | BP29: SI | BQ29: NO | BR29: 1 | BS29: Ninguno | BU29: =IF($A29<>"", DATE(YEAR($A29),MONTH($A29),DAY($A29)),"") -> 46192 | BV29: =IF($E29<>"",DATE(YEAR($E29),MONTH($E29),DAY($E29)),"") -> 46196 | BW29: =IF($E29<>"",TEXT($E29,"HH"),"") -> 13 | BZ29: =IF(B29<>"",VALUE(LEFT(B29)),"") -> 5 | CA29: {=IF($A29<>"",INDEX(LISTA!$M$2:$N$27,MATCH($BC29,LISTA!$N$2:$N$27,0),1),"")} -> 15 | CB29: =IF($A29<>"",MONTH(BU29),"") -> 6 | CC29: =IF($BX29<>"",MONTH(BX29),"")
A30: 46200.641 | B30: 5 - CTO - EXCEDE METRAJE | C30: MASIVO RESIDENCIAL | D30: NAYELI | E30: 46203.667 | F30: Rechazado Por Falta De Infraestructura De Red - Campo | G30: 104904353 | H30: 88676944 | I30: JULIANA | J30: 929113007 | K30: DNI | L30: 76186707 | M30: MEDALYT ROCIO COAQUERA PONGO | N30: 35617 | O30: TACNA | P30: 220201 | AN30: Tacna | AQ30: TEODORO | AR30: IRMA | AS30: DF0889538@GMAIL.COM | AU30: 929113007 | AV30: 929113007 | AW30: URB. EL CHOLOLO MZ A2 LOTE 3, TACNA CERCADO. | AX30: 1 | AY30: 1 | AZ30: -18.022236, -70.27216687 | BA30: POR LA AV. ZARUMILLA | BB30: TCNA147-F | BC30: TACNA | BD30: =IF(COUNTA(Q30:AP30)>0,INDEX(Q30:AP30,,max(IF(Q30:AP30<>"",COLUMN(Q30:AP30)))-16),"") -> Tacna | BE30: FTTH | BF30: NO | BG30: ALTA NUEVA | BL30: 1 PLAY + L1MAX | BM30: Campaña Regular | BN30: 110 | BO30: 1000MBPS | BP30: SI | BQ30: NO | BR30: Ninguno | BS30: 1 | BU30: =IF($A30<>"", DATE(YEAR($A30),MONTH($A30),DAY($A30)),"") -> 46200 | BV30: =IF($E30<>"",DATE(YEAR($E30),MONTH($E30),DAY($E30)),"") -> 46203 | BW30: =IF($E30<>"",TEXT($E30,"HH"),"") -> 16 | BZ30: =IF(B30<>"",VALUE(LEFT(B30)),"") -> 5 | CA30: {=IF($A30<>"",INDEX(LISTA!$M$2:$N$27,MATCH($BC30,LISTA!$N$2:$N$27,0),1),"")} -> 24 | CB30: =IF($A30<>"",MONTH(BU30),"") -> 6 | CC30: =IF($BX30<>"",MONTH(BX30),"")
A31: 46195.416 | B31: 5 - BAJA-NO DESEA | C31: MASIVO RESIDENCIAL | D31: NAYELI | E31: 46196.583 | F31: CLIENTE QUERIA SU INSTALACION PARA ESE MISMO DIA, SI O SI, NO DESEA REPROGRAMACION | G31: 104737775 | H31: 88515175 | I31: JESSICA | J31: 917707080 | K31: DNI | L31: 70090949 | M31: KRISTIAN COLLANQUI FLORES | N31: 33904 | O31: PUNO | P31: 200604 | AL31: San Román | AQ31: PASCUAL MARCIAL | AR31: LEONCIA | AS31: kristiancollanqui2705@gmail.com | AU31: 917707080 | AV31: 917707080 | AW31: kristiancollanqui2705@gmail.com | AX31: 2 | AY31: NA | AZ31: -15.466703, -70.143151 | BA31: JIRON COPACABANA | BB31: PUJL123-F | BC31: PUNO | BD31: =IF(COUNTA(Q31:AP31)>0,INDEX(Q31:AP31,,max(IF(Q31:AP31<>"",COLUMN(Q31:AP31)))-16),"") -> San Román | BE31: FTTH | BF31: SI | BG31: ALTA NUEVA | BL31: 1 PLAY | BM31: Campaña Promo Mediana | BN31: 89 | BO31: 400MBPS | BP31: NO | BQ31: NO | BR31: Ninguno | BS31: 1 | BU31: =IF($A31<>"", DATE(YEAR($A31),MONTH($A31),DAY($A31)),"") -> 46195 | BV31: =IF($E31<>"",DATE(YEAR($E31),MONTH($E31),DAY($E31)),"") -> 46196 | BW31: =IF($E31<>"",TEXT($E31,"HH"),"") -> 14 | BZ31: =IF(B31<>"",VALUE(LEFT(B31)),"") -> 5 | CA31: {=IF($A31<>"",INDEX(LISTA!$M$2:$N$27,MATCH($BC31,LISTA!$N$2:$N$27,0),1),"")} -> 22 | CB31: =IF($A31<>"",MONTH(BU31),"") -> 6 | CC31: =IF($BX31<>"",MONTH(BX31),"")
A32: 46191.461 | B32: 5 - BAJA-NO DESEA | C32: MASIVO RESIDENCIAL | D32: NAYELI | E32: 46197.375 | F32: VENTA ANTIGUO, CLIENTE RECIBIO PROMOCION DE CLARO SOBRE SU INSTALACION ACTUAL, DECIDE QUEDARSE CON ELLOS. | G32: 104642463 | H32: 88433432 | I32: JESSICA | J32: 945547763 | K32: DNI | L32: 21122076 | M32: RAUL DIEGO YARASCA MANDUJANO | N32: 25972 | O32: JUNIN | P32: 110325 | AB32: Chanchamayo | AQ32: FELIX | AR32: ESTEFANIA | AS32: ryarasca123@gmail.com | AU32: 945547763 | AV32: 945547763 | AW32: AV. ASHANINKA 235 URB. EL PARAISO | AX32: 4 | AY32: 4A | AZ32: -11.0675295, -75.339234545 | BA32: IEP. Santa Maria Reyna | BB32: JNCM008-F | BC32: JUNIN | BD32: =IF(COUNTA(Q32:AP32)>0,INDEX(Q32:AP32,,max(IF(Q32:AP32<>"",COLUMN(Q32:AP32)))-16),"") -> Chanchamayo | BE32: FTTH | BF32: SI | BG32: ALTA NUEVA | BL32: 1 PLAY | BM32: Campaña Promo Mediana | BN32: 89 | BO32: 400MBPS | BP32: NO | BQ32: NO | BR32: Ninguno | BS32: 1 | BU32: =IF($A32<>"", DATE(YEAR($A32),MONTH($A32),DAY($A32)),"") -> 46191 | BV32: =IF($E32<>"",DATE(YEAR($E32),MONTH($E32),DAY($E32)),"") -> 46197 | BW32: =IF($E32<>"",TEXT($E32,"HH"),"") -> 09 | BZ32: =IF(B32<>"",VALUE(LEFT(B32)),"") -> 5 | CA32: {=IF($A32<>"",INDEX(LISTA!$M$2:$N$27,MATCH($BC32,LISTA!$N$2:$N$27,0),1),"")} -> 14 | CB32: =IF($A32<>"",MONTH(BU32),"") -> 6 | CC32: =IF($BX32<>"",MONTH(BX32),"")
A33: 46195.545 | B33: 5 - BAJA-NO DESEA | C33: MASIVO RESIDENCIAL | D33: NAYELI | E33: 46197.583 | F33: LLAMARON A CLIENTE PARA INDICARLE QUE SU RED ESTA SATURADA, CLIENTE CONTRATÓ CON OTRO OPERADOR | G33: 104748456 | H33: 88524046 | I33: ANGHELL | J33: 963188744 | K33: DNI | L33: 74079616 | M33: PAMELA YVETTE MALDONADO QUISPE | N33: 35257 | O33: AREQUIPA | P33: 040109 | T33: Arequipa | AQ33: VICTOR MANUEL | AR33: DIONISIA | AS33: maldonadopamela986@gmail.com | AU33: 963188744 | AV33: 963188744 | AW33: urb CAMPO DE MARTE MZ P LT 42, PAUCARPATA, AREQUIPA | AX33: 3 | AY33: 0 | AZ33: -16.427180557097067, -71.4941595331016 | BA33: CALLE TUPAC AMARU | BB33: AQPP047 | BC33: AREQUIPA | BD33: =IF(COUNTA(Q33:AP33)>0,INDEX(Q33:AP33,,max(IF(Q33:AP33<>"",COLUMN(Q33:AP33)))-16),"") -> Arequipa | BE33: HFC | BF33: SI | BG33: ALTA NUEVA | BL33: 1 PLAY | BM33: Campaña Promo Mediana | BN33: 89 | BO33: 400MBPS | BP33: NO | BQ33: NO | BR33: Ninguno | BS33: 1 | BU33: =IF($A33<>"", DATE(YEAR($A33),MONTH($A33),DAY($A33)),"") -> 46195 | BV33: =IF($E33<>"",DATE(YEAR($E33),MONTH($E33),DAY($E33)),"") -> 46197 | BW33: =IF($E33<>"",TEXT($E33,"HH"),"") -> 14 | BZ33: =IF(B33<>"",VALUE(LEFT(B33)),"") -> 5 | CA33: {=IF($A33<>"",INDEX(LISTA!$M$2:$N$27,MATCH($BC33,LISTA!$N$2:$N$27,0),1),"")} -> 7 | CB33: =IF($A33<>"",MONTH(BU33),"") -> 6 | CC33: =IF($BX33<>"",MONTH(BX33),"")
A34: 46200.72 | B34: 5 - BAJA-MALA INFO VENTA | C34: MASIVO RESIDENCIAL | D34: NAYELI | E34: 46202.458 | F34: Rechazado Por Mala Oferta - Campo | G34: 104908264 | H34: 88678456 | I34: GABRIEL | J34: 912145179 | K34: DNI | L34: 74650613 | M34: JIMENEZ VASQUEZ SOLIS, JACK ISMAEL | N34: 35732 | O34: LIMA METROPOLITANA | P34: 150132 | AF34: San Juan de Lurigancho | AQ34: ABEL | AR34: YOVANA | AS34: jackismaeljimenezvasquezsolis@gmail.com | AU34: 912145179 | AV34: 912145179 | AW34: jr tahuantinsuyo 638 URB Zarate | AX34: 4 | AY34: 5 | AZ34: -12.027747, -77.002502 | BA34: A 1 CDRA DE LA COMISARIA ZARATE | BB34: LMJL062 | BC34: LIMA METROPOLITANA | BD34: =IF(COUNTA(Q34:AP34)>0,INDEX(Q34:AP34,,max(IF(Q34:AP34<>"",COLUMN(Q34:AP34)))-16),"") -> San Juan de Lurigancho | BE34: HFC | BF34: NO | BG34: ALTA NUEVA | BL34: 1 PLAY | BM34: Campaña Regular | BN34: 89 | BO34: 400MBPS | BP34: NO | BQ34: NO | BR34: Ninguno | BS34: Ninguno | BU34: =IF($A34<>"", DATE(YEAR($A34),MONTH($A34),DAY($A34)),"") -> 46200 | BV34: =IF($E34<>"",DATE(YEAR($E34),MONTH($E34),DAY($E34)),"") -> 46202 | BW34: =IF($E34<>"",TEXT($E34,"HH"),"") -> 11 | BZ34: =IF(B34<>"",VALUE(LEFT(B34)),"") -> 5 | CA34: {=IF($A34<>"",INDEX(LISTA!$M$2:$N$27,MATCH($BC34,LISTA!$N$2:$N$27,0),1),"")} -> 1 | CB34: =IF($A34<>"",MONTH(BU34),"") -> 6 | CC34: =IF($BX34<>"",MONTH(BX34),"")
A35: 46200.44 | B35: 4 - FLIPPING | C35: MASIVO RESIDENCIAL | D35: NAYELI | E35: 46200.667 | F35: PROCEDE | G35: 104889152 | H35: 88671317 | I35: ANTHONELLA | J35: 974306888 | K35: DNI | L35: 74861925 | M35: JUAN JOSE MARTIN GUTIERREZ ESCALANTE | N35: 35107 | O35: LIMA METROPOLITANA | P35: 150101 | AF35: Carabayllo | AQ35: GILBERTO | AR35: DELA | AS35: JUANJO.GUTIERRESES GMAIL.COM | AU35: 974306888 | AV35: 974306888 | AW35: CALLE LOS LAURES MZ D LT 33 , UB LA RIVERA CARABAYLLO | AX35: 1 | AY35: ND | AZ35: -11.878564699683325 -77.02282265736812 | BA35: URBANIZACION LA RIVERA | BB35: LMBY009-S | BC35: LIMA METROPOLITANA | BD35: =IF(COUNTA(Q35:AP35)>0,INDEX(Q35:AP35,,max(IF(Q35:AP35<>"",COLUMN(Q35:AP35)))-16),"") -> Carabayllo | BE35: FTTH | BF35: SI | BG35: ALTA NUEVA | BL35: 1 PLAY | BM35: Campaña Regular | BN35: 94 | BO35: 400MBPS | BP35: NO | BQ35: SI | BR35: Ninguno | BS35: Ninguno | BU35: =IF($A35<>"", DATE(YEAR($A35),MONTH($A35),DAY($A35)),"") -> 46200 | BV35: =IF($E35<>"",DATE(YEAR($E35),MONTH($E35),DAY($E35)),"") -> 46200 | BW35: =IF($E35<>"",TEXT($E35,"HH"),"") -> 16 | BZ35: =IF(B35<>"",VALUE(LEFT(B35)),"") -> 4 | CA35: {=IF($A35<>"",INDEX(LISTA!$M$2:$N$27,MATCH($BC35,LISTA!$N$2:$N$27,0),1),"")} -> 1 | CB35: =IF($A35<>"",MONTH(BU35),"") -> 6 | CC35: =IF($BX35<>"",MONTH(BX35),"")
A36: 46193.495 | B36: 4 - FLIPPING | C36: MASIVO RESIDENCIAL | D36: PAOLA | E36: 46200.583 | F36: REPRO PARA EL 27/06 | G36: 104702456 | H36: 88479774 | I36: JUAN DIEGO | J36: 920477366 | K36: DNI | L36: 76423649 | M36: ZHANDLER PINEDA SANCHEZ | N36: 37529 | O36: HUANUCO | P36: 100102 | Z36: Huánuco | AQ36: Zacarias | AR36: Mercedes | AS36: zhatisa3909@gmail.com | AU36: 920477366 | AV36: 920477366 | AW36: jiron brasil mz t lt 1 URBANIZACION san luis sector 12 | AX36: 2 | AY36: 1A | AZ36: -9.9401925, -76.236067995 | BA36: Avenida Ricardo Palma | BB36: HNAM002-F | BC36: HUANUCO | BD36: =IF(COUNTA(Q36:AP36)>0,INDEX(Q36:AP36,,max(IF(Q36:AP36<>"",COLUMN(Q36:AP36)))-16),"") -> Huánuco | BE36: FTTH | BF36: SI | BG36: ALTA NUEVA | BL36: 1 PLAY | BM36: Campaña Regular | BN36: 110 | BO36: 500MBPS | BP36: SI | BQ36: NO | BR36: Ninguno | BS36: 1 | BU36: =IF($A36<>"", DATE(YEAR($A36),MONTH($A36),DAY($A36)),"") -> 46193 | BV36: =IF($E36<>"",DATE(YEAR($E36),MONTH($E36),DAY($E36)),"") -> 46200 | BW36: =IF($E36<>"",TEXT($E36,"HH"),"") -> 14 | BZ36: =IF(B36<>"",VALUE(LEFT(B36)),"") -> 4 | CA36: {=IF($A36<>"",INDEX(LISTA!$M$2:$N$27,MATCH($BC36,LISTA!$N$2:$N$27,0),1),"")} -> 12 | CB36: =IF($A36<>"",MONTH(BU36),"") -> 6 | CC36: =IF($BX36<>"",MONTH(BX36),"")
A37: 46188.459 | B37: 4 - FAC TEC-TORRE NO HABILITADA | C37: MASIVO RESIDENCIAL | D37: NAYELI | E37: 46190.375 | F37: EDIFICIO NO HABILITADO CON CLARO, NO PERMITEN TENDIDO AEREO | G37: 104547386 | H37: 88346622 | I37: JESSICA | J37: 987702720 | K37: DNI | L37: 42078293 | M37: JORGE ANIBAL BADO ESPINO | N37: 30630 | O37: LIMA | P37: 140110 | AF37: San Borja | AQ37: JORGE DANILO | AR37: MYRIAM TATIANA | AS37: bado.jorge@gmail.com | AU37: 987702720 | AV37: 987702720 | AW37: Avenida Juan Bielovucic Cavalier 157 Urbanización Chacarilla del Estanque | AX37: 5 | AY37: 501 | AZ37: -12.103503, -76.980941 | BA37: Puerta 4 auditorio pentagonito | BB37: 5222B06AS | BC37: LIMA METROPOLITANA | BD37: =IF(COUNTA(Q37:AP37)>0,INDEX(Q37:AP37,,max(IF(Q37:AP37<>"",COLUMN(Q37:AP37)))-16),"") -> San Borja | BE37: FTTH | BF37: NO | BG37: ALTA NUEVA | BL37: 1 PLAY + L1MAX | BM37: Campaña Regular PRO | BN37: 110 | BO37: 400MBPS | BP37: SI | BQ37: NO | BR37: Ninguno | BS37: 1 | BU37: =IF($A37<>"", DATE(YEAR($A37),MONTH($A37),DAY($A37)),"") -> 46188 | BV37: =IF($E37<>"",DATE(YEAR($E37),MONTH($E37),DAY($E37)),"") -> 46190 | BW37: =IF($E37<>"",TEXT($E37,"HH"),"") -> 09 | BZ37: =IF(B37<>"",VALUE(LEFT(B37)),"") -> 4 | CA37: {=IF($A37<>"",INDEX(LISTA!$M$2:$N$27,MATCH($BC37,LISTA!$N$2:$N$27,0),1),"")} -> 1 | CB37: =IF($A37<>"",MONTH(BU37),"") -> 6 | CC37: =IF($BX37<>"",MONTH(BX37),"")
A38: 46198.74 | B38: 3 - REPROGRAMADA | C38: MASIVO RESIDENCIAL | D38: NAYELI | E38: 46203.375 | F38: EN EJECUCION | G38: 104848535 | H38: 88625537 | I38: BRITNEY | J38: 955847780 | K38: DNI | L38: 40152975 | M38: GROWER HONORATO GARRO HUERTAS | N38: 28048 | O38: ANCASH | P38: 020509 | AF38: Los Olivos | AQ38: Fernando | AR38: Jacoba | AS38: growergarrohuertas@gmail.com | AU38: 955 847 780 | AV38: 955 847 780 | AW38: calle las gardenias mz c lt10 | AX38: 3 | AY38: 1 | AZ38: -11.944502 , -77.073282 | BA38: URBANIZACIÓN LAS GARDENIAS DE PRO | BB38: LMLO101 | BC38: LIMA METROPOLITANA | BD38: =IF(COUNTA(Q38:AP38)>0,INDEX(Q38:AP38,,max(IF(Q38:AP38<>"",COLUMN(Q38:AP38)))-16),"") -> Los Olivos | BE38: HFC | BF38: SI | BG38: ALTA NUEVA | BL38: 1 PLAY + L1MAX | BM38: Campaña Regular | BN38: 110 | BO38: 500MBPS | BP38: SI | BQ38: NO | BR38: Ninguno | BS38: Ninguno | BU38: =IF($A38<>"", DATE(YEAR($A38),MONTH($A38),DAY($A38)),"") -> 46198 | BV38: =IF($E38<>"",DATE(YEAR($E38),MONTH($E38),DAY($E38)),"") -> 46203 | BW38: =IF($E38<>"",TEXT($E38,"HH"),"") -> 09 | BZ38: =IF(B38<>"",VALUE(LEFT(B38)),"") -> 3 | CA38: {=IF($A38<>"",INDEX(LISTA!$M$2:$N$27,MATCH($BC38,LISTA!$N$2:$N$27,0),1),"")} -> 1 | CB38: =IF($A38<>"",MONTH(BU38),"") -> 6 | CC38: =IF($BX38<>"",MONTH(BX38),"")
A39: 46199.696 | B39: 3 - PROGRAMADA | C39: MASIVO RESIDENCIAL | D39: NAYELI | E39: 46206.375 | F39: EN EJECUCION | G39: 104876137 | H39: 88661759 | I39: BRITNEY | J39: 931290676 | K39: DNI | L39: 41673092 | M39: WALTER GUTIERREZ VILLANUEVA | N39: 30241 | O39: AYACUCHO | P39: 050112 | U39: Huamanga | AQ39: Celedonio | AR39: Alberta | AS39: Walter_gv@hotmail.com | AU39: 931290676 | AV39: 931290676 | AW39: Prolongación manco capac N° 1277 | AX39: 3 | AY39: 1 | AZ39: -13.154932, -74.23124 | BA39: Prolongación manco capac | BB39: AYAY016-S | BC39: AYACUCHO | BD39: =IF(COUNTA(Q39:AP39)>0,INDEX(Q39:AP39,,max(IF(Q39:AP39<>"",COLUMN(Q39:AP39)))-16),"") -> Huamanga | BE39: FTTH | BF39: NO | BG39: ALTA NUEVA | BL39: 1 PLAY | BM39: Campaña Promo Mediana | BN39: 89 | BO39: 400MBPS | BP39: NO | BQ39: NO | BR39: Ninguno | BS39: 1 | BU39: =IF($A39<>"", DATE(YEAR($A39),MONTH($A39),DAY($A39)),"") -> 46199 | BV39: =IF($E39<>"",DATE(YEAR($E39),MONTH($E39),DAY($E39)),"") -> 46206 | BW39: =IF($E39<>"",TEXT($E39,"HH"),"") -> 09 | BZ39: =IF(B39<>"",VALUE(LEFT(B39)),"") -> 3 | CA39: {=IF($A39<>"",INDEX(LISTA!$M$2:$N$27,MATCH($BC39,LISTA!$N$2:$N$27,0),1),"")} -> 8 | CB39: =IF($A39<>"",MONTH(BU39),"") -> 6 | CC39: =IF($BX39<>"",MONTH(BX39),"")
A40: 46200.406 | B40: 3 - PROGRAMADA | C40: MASIVO RESIDENCIAL | D40: NAYELI | E40: 46204.667 | F40: EN EJECUCION | G40: 104887811 | H40: 88670937 | I40: JUAN DIEGO | J40: 935507175 | K40: DNI | L40: 26961099 | M40: CESAR WILMAN SALAZAR GAMBOA | N40: 28087 | O40: CAJAMARCA | P40: 060101 | V40: Cajabamba | AQ40: ENRIQUE | AR40: WILBERTA | AS40: Frankzrodriguezsalazar@gmail.com | AU40: 935 507 175 | AV40: 935 507 175 | AW40: JIRON SUAREZ 190 | AX40: 1 | AY40: NA | AZ40: -7.622846114469324, -78.04942980699167 | BA40: JIRON JOSE LEAL | BB40: CJCB005-F | BC40: CAJAMARCA | BD40: =IF(COUNTA(Q40:AP40)>0,INDEX(Q40:AP40,,max(IF(Q40:AP40<>"",COLUMN(Q40:AP40)))-16),"") -> Cajabamba | BE40: FTTH | BF40: SI | BG40: ALTA NUEVA | BL40: 1 PLAY | BM40: Campaña Regular | BN40: 100 | BO40: 800MBPS | BP40: NO | BQ40: NO | BR40: Ninguno | BS40: 1 | BU40: =IF($A40<>"", DATE(YEAR($A40),MONTH($A40),DAY($A40)),"") -> 46200 | BV40: =IF($E40<>"",DATE(YEAR($E40),MONTH($E40),DAY($E40)),"") -> 46204 | BW40: =IF($E40<>"",TEXT($E40,"HH"),"") -> 16 | BZ40: =IF(B40<>"",VALUE(LEFT(B40)),"") -> 3 | CA40: {=IF($A40<>"",INDEX(LISTA!$M$2:$N$27,MATCH($BC40,LISTA!$N$2:$N$27,0),1),"")} -> 9 | CB40: =IF($A40<>"",MONTH(BU40),"") -> 6 | CC40: =IF($BX40<>"",MONTH(BX40),"")
...

Sheet PREVENTAS
A1: Marca temporal | B1: STATUS | C1: SEGMENTO | D1: ASESOR BO | E1: PROGRAMACION BO | F1: COMENTARIOS BO | G1: SEC | H1: SOT | I1: ASESOR | J1: LEAD | K1: TIPO DOCUMENTO | L1: N° DOCUMENTO | M1: NOMBRE COMPLETO CLIENTE | N1: FECHA NACIMIENTO | O1: LUGAR NACIMIENTO | P1: UBIGEO | Q1: AMAZONAS | R1: ANCASH | S1: APURIMAC | T1: AREQUIPA | U1: AYACUCHO | V1: CAJAMARCA | W1: CALLAO | X1: CUSCO | Y1: HUANCAVELICA | Z1: HUANUCO | AA1: ICA | AB1: JUNIN | AC1: LA LIBERTAD | AD1: LAMBAYEQUE | AE1: LIMA | AF1: LIMA METROPOLITANA | AG1: LORETO | AH1: MADRE DE DIOS | AI1: MOQUEGUA | AJ1: PASCO | AK1: PIURA | AL1: PUNO | AM1: SAN MARTIN | AN1: TACNA | AO1: TUMBES | AP1: UCAYALI | AQ1: NOMBRE PADRE | AR1: NOMBRE MADRE | AS1: CORREO ELECTRONICO | AT1: TELF REGISTRO | AU1: TELF GRABACION | AV1: TELF REFERENCIA | AW1: DIRECCION INSTALACION | AX1: PISO | AY1: INTERIOR | AZ1: COORDENADAS | BA1: REFERENCIAS | BB1: PLANO | BC1: DEPARTAMENTO | BD1: PROV / DISTRITO | BE1: TECNOLOGIA | BF1: FULL CLARO | BG1: OPERACION | BH1: OPERADOR ORIGEN | BI1: TELF A PORTAR | BJ1: MODALIDAD | BK1: TIPO SERVICIO | BL1: SERVICIO A CONTRATAR | BM1: OFERTA COMERCIAL ALTA NUEVA | BN1: PRECIO REGULAR | BO1: VELOCIDAD PLAN | BP1: LIGA1 MAX | BQ1: TELEFONO | BR1: N° DECODIFICADORES | BS1: N° MESH | BT1: FECHA INSTALACIÓN | BU1: ORDEN INSTALACION | BV1: FECHA REGISTRO | BW1: FECHA PROGRAMACION | BX1: TRAMO PROGRAMACION | BY1: COD STATUS | BZ1: COD DPTO | CA1: MES REG | CB1: MES INSTAL | CC1: CUSTOMER ID
A2: 46179.52 | B2: 5 - INSTALADA | C2: MASIVO RESIDENCIAL | D2: NAYELI | E2: 46185.583 | F2: LYBTEL | G2: 104457724 | H2: 88271126 | I2: ROCIO | J2: 998357850 | K2: DNI | L2: 43729341 | M2: HUGO HERRERA NUÑEZ | N2: 31658 | O2: LIMA | P2: 150131 | AF2: Santiago de Surco | AQ2: HUGO | AR2: MARIA | AS2: jnunezo@hotmail.es | AT2: 997351175 | AU2: 997351175 | AV2: 997351175 | AW2: ayacucho 942 santiago de surco dto 402 | AX2: 4 | AY2: 402 | AZ2: -12.136189335877416, -76.99837869182522 | BA2: AV DOñA RAQUEL | BB2: LMSC293-F | BC2: LIMA METROPOLITANA | BD2: =IF(COUNTA(Q2:AP2)>0,INDEX(Q2:AP2,,max(IF(Q2:AP2<>"",COLUMN(Q2:AP2)))-16),"") -> Santiago de Surco | BE2: FTTH | BF2: NO | BG2: ALTA NUEVA | BL2: 2 PLAY + TV ESTANDAR | BM2: Campaña Regular | BN2: 170 | BO2: 400MBPS | BP2: NO | BQ2: NO | BR2: Ninguno | BS2: Ninguno | BT2: 46185 | BU2: 1 | BV2: =IF($A2<>"", DATE(YEAR($A2),MONTH($A2),DAY($A2)),"") -> 46179 | BW2: =IF($E2<>"",DATE(YEAR($E2),MONTH($E2),DAY($E2)),"") -> 46185 | BX2: =IF($E2<>"",TEXT($E2,"HH"),"") -> 14 | BY2: =IF(B2<>"",VALUE(LEFT(B2)),"") -> 5 | BZ2: {=IF($A2<>"",INDEX(LISTA!$M$2:$N$27,MATCH($BC2,LISTA!$N$2:$N$27,0),1),"")} -> 1 | CA2: =IF($A2<>"",MONTH(BV2),"") -> 6 | CB2: =IF($BT2<>"",MONTH(BT2),"") -> 6 | CC2: 57896117
A3: 46184.543 | B3: 5 - INSTALADA | C3: MASIVO RESIDENCIAL | D3: NAYELI | E3: 46185.667 | F3: LYBTEL | G3: 104449975 | H3: 88267394 | I3: ROCIO | J3: 985871277 | K3: DNI | L3: 43252312 | M3: SUSAN IVONNE HEREDIA CORDOVA | N3: 31371 | O3: JUNIN | P3: 110101 | AF3: San Martín de Porres | AQ3: luis | AR3: lucila | AS3: Gabycina@hotmail.com | AT3: 985871277 | AU3: 985871277 | AV3: 985871277 | AW3: Urb.San german Jr Ávila Godoy 657 | AX3: 4 | AY3: 1 | AZ3: -12.015793, -77.071245 | BA3: ingreso es por el jardín inicial Germancito | BB3: LMMP233-F | BC3: LIMA METROPOLITANA | BD3: =IF(COUNTA(Q3:AP3)>0,INDEX(Q3:AP3,,max(IF(Q3:AP3<>"",COLUMN(Q3:AP3)))-16),"") -> San Martín de Porres | BE3: FTTH | BF3: SI | BG3: ALTA NUEVA | BL3: 1 PLAY | BM3: Campaña Regular | BN3: 110 | BO3: 500MBPS | BP3: SI | BQ3: NO | BR3: Ninguno | BS3: 1 | BT3: 46186 | BU3: 1 | BV3: =IF($A3<>"", DATE(YEAR($A3),MONTH($A3),DAY($A3)),"") -> 46184 | BW3: =IF($E3<>"",DATE(YEAR($E3),MONTH($E3),DAY($E3)),"") -> 46185 | BX3: =IF($E3<>"",TEXT($E3,"HH"),"") -> 16 | BY3: =IF(B3<>"",VALUE(LEFT(B3)),"") -> 5 | BZ3: {=IF($A3<>"",INDEX(LISTA!$M$2:$N$27,MATCH($BC3,LISTA!$N$2:$N$27,0),1),"")} -> 1 | CA3: =IF($A3<>"",MONTH(BV3),"") -> 6 | CB3: =IF($BT3<>"",MONTH(BT3),"") -> 6 | CC3: 57895552
A4: 46190.379 | B4: 5 - INSTALADA | C4: MASIVO RESIDENCIAL | D4: NAYELI | E4: 46191.583 | F4: PROCEDE/ EDIFICIO HABILITADO | G4: 104605460 | H4: 88405389 | I4: JESSICA | J4: 987579907 | K4: DNI | L4: 70350550 | M4: CLAUDIA ISABEL GIL VIDAL | N4: 33362 | O4: LIMA | P4: 140115 | AF4: Miraflores | AQ4: FERNANDO HUMBERTO | AR4: IRMA BETTY | AS4: cgilvidal@gmail.com | AT4: 987579907 | AU4: 987579907 | AV4: 987579907 | AW4: AVENIDA PASEO DE LA REPUBLICA 6373 URBANIZACION SAN ANTONIO | AX4: 16 | AY4: 1601 | AZ4: -12.132422, -77.021475 | BA4: VIA EXPRESA LUIS FERNAN BEDOYA REYES | BB4: LMMF083 | BC4: LIMA METROPOLITANA | BD4: =IF(COUNTA(Q4:AP4)>0,INDEX(Q4:AP4,,max(IF(Q4:AP4<>"",COLUMN(Q4:AP4)))-16),"") -> Miraflores | BE4: HFC | BF4: SI | BG4: ALTA NUEVA | BL4: 1 PLAY + L1MAX | BM4: Campaña Regular PRO | BN4: 110 | BO4: 500MBPS | BP4: SI | BQ4: NO | BR4: Ninguno | BS4: Ninguno | BT4: 46191 | BU4: 1 | BV4: =IF($A4<>"", DATE(YEAR($A4),MONTH($A4),DAY($A4)),"") -> 46190 | BW4: =IF($E4<>"",DATE(YEAR($E4),MONTH($E4),DAY($E4)),"") -> 46191 | BX4: =IF($E4<>"",TEXT($E4,"HH"),"") -> 14 | BY4: =IF(B4<>"",VALUE(LEFT(B4)),"") -> 5 | BZ4: {=IF($A4<>"",INDEX(LISTA!$M$2:$N$27,MATCH($BC4,LISTA!$N$2:$N$27,0),1),"")} -> 1 | CA4: =IF($A4<>"",MONTH(BV4),"") -> 6 | CB4: =IF($BT4<>"",MONTH(BT4),"") -> 6 | CC4: 57934319
A5: 46190.494 | B5: 5 - INSTALADA | C5: MASIVO RESIDENCIAL | D5: PAOLA | E5: 46193.458 | F5: LLAMAR 12:30 | G5: 104649549 | H5: 88437602 | I5: PAOLA | J5: 915992860 | K5: DNI | L5: 40537157 | M5: JOHANA MEDALITH MELENDEZ CHINGA | N5: 29369 | O5: LIMA | P5: 140101 | AE5: Huaura | AQ5: JULIO | AR5: ELENA | AS5: RICHARDTJ_3@HOTMAIL.COM | AT5: 963877220 | AU5: 963877220 | AV5: 915992860 | AW5: Urb Martir Jose Olaya mz g lote 12 | AX5: 2 | AY5: NA | AZ5: -11.09480528124759, -77.62592378552375 | BA5: JR 28 OCTUBRE | BB5: LMCQ002 | BC5: LIMA | BD5: =IF(COUNTA(Q5:AP5)>0,INDEX(Q5:AP5,,max(IF(Q5:AP5<>"",COLUMN(Q5:AP5)))-16),"") -> Huaura | BE5: HFC | BF5: SI | BG5: ALTA NUEVA | BL5: 1 PLAY | BM5: Campaña Regular | BN5: 110 | BO5: 500MBPS | BP5: NO | BQ5: NO | BR5: 1 | BS5: 1 | BT5: 46192 | BU5: 1 | BV5: =IF($A5<>"", DATE(YEAR($A5),MONTH($A5),DAY($A5)),"") -> 46190 | BW5: =IF($E5<>"",DATE(YEAR($E5),MONTH($E5),DAY($E5)),"") -> 46193 | BX5: =IF($E5<>"",TEXT($E5,"HH"),"") -> 11 | BY5: =IF(B5<>"",VALUE(LEFT(B5)),"") -> 5 | BZ5: {=IF($A5<>"",INDEX(LISTA!$M$2:$N$27,MATCH($BC5,LISTA!$N$2:$N$27,0),1),"")} -> 3 | CA5: =IF($A5<>"",MONTH(BV5),"") -> 6 | CB5: =IF($BT5<>"",MONTH(BT5),"") -> 6 | CC5: 57946138
A6: 46192.657 | B6: 5 - INSTALADA | C6: MASIVO RESIDENCIAL | D6: PAOLA | E6: 46193.458 | F6: SE MANDA A ANULAR SOT LOS DATOS DE DIRECCIÓN ES INCORRECTO/ CORREGIDO | G6: 104692164 | H6: 88475969 | I6: SAHIR | J6: 995048683 | K6: DNI | L6: 43379508 | M6: JULIO RAMON CHUNG GONZALES | N6: 31436 | O6: LIMA METROPOLITANA | P6: 150121 | AF6: Lince | AQ6: luis fernando | AR6: elvira marina | AS6: julianchungonzales@gmail.com | AT6: 995048683 | AU6: 995048683 | AV6: 995048683 | AW6: JIRON INCA GARCILASO DE LA VEGA 1874 URBANIZACION RISSO LINCE | AX6: 1 | AY6: 1 | AZ6: -12.084034, -77.040746 | BA6: av canebaro | BB6: LMLC077-F | BC6: LIMA METROPOLITANA | BD6: =IF(COUNTA(Q6:AP6)>0,INDEX(Q6:AP6,,max(IF(Q6:AP6<>"",COLUMN(Q6:AP6)))-16),"") -> Lince | BE6: FTTH | BF6: SI | BG6: ALTA NUEVA | BL6: 2PLAY + TELF | BM6: Campaña Regular | BN6: 94 | BO6: 400MBPS | BP6: NO | BQ6: SI | BR6: Ninguno | BS6: 1 | BT6: 46194 | BU6: 1 | BV6: =IF($A6<>"", DATE(YEAR($A6),MONTH($A6),DAY($A6)),"") -> 46192 | BW6: =IF($E6<>"",DATE(YEAR($E6),MONTH($E6),DAY($E6)),"") -> 46193 | BX6: =IF($E6<>"",TEXT($E6,"HH"),"") -> 11 | BY6: =IF(B6<>"",VALUE(LEFT(B6)),"") -> 5 | BZ6: {=IF($A6<>"",INDEX(LISTA!$M$2:$N$27,MATCH($BC6,LISTA!$N$2:$N$27,0),1),"")} -> 1 | CA6: =IF($A6<>"",MONTH(BV6),"") -> 6 | CB6: =IF($BT6<>"",MONTH(BT6),"") -> 6 | CC6: 57955168
